# Django populate reentrant error

[Django populate reentrant error - Private](https://chatgpt.com/c/681c8f4a-3464-8002-84ac-879e5cc03c33)
[Django populate reentrant error - Shared]()

Help me understand this error trace. Help me understand what the command is actually doing. Help me understand what `RuntimeError: populate() isn't reentrant` means:

```bash
personal-assistantflynntknapp@DELL-DESKTOP:~/Programming/personal-assistant$ python manage.py check --deploy
Traceback (most recent call last):
  File "/home/flynntknapp/Programming/personal-assistant/manage.py", line 22, in <module>
    main()
  File "/home/flynntknapp/Programming/personal-assistant/manage.py", line 18, in main
    execute_from_command_line(sys.argv)
  File "/home/flynntknapp/.local/share/virtualenvs/personal-assistant-Y8r_Smg_/lib/python3.11/site-packages/django/core/management/__init__.py", line 446, in execute_from_command_line
    utility.execute()
  File "/home/flynntknapp/.local/share/virtualenvs/personal-assistant-Y8r_Smg_/lib/python3.11/site-packages/django/core/management/__init__.py", line 420, in execute
    django.setup()
  File "/home/flynntknapp/.local/share/virtualenvs/personal-assistant-Y8r_Smg_/lib/python3.11/site-packages/django/__init__.py", line 24, in setup
    apps.populate(settings.INSTALLED_APPS)
  File "/home/flynntknapp/.local/share/virtualenvs/personal-assistant-Y8r_Smg_/lib/python3.11/site-packages/django/apps/registry.py", line 83, in populate
    raise RuntimeError("populate() isn't reentrant")
RuntimeError: populate() isn't reentrant
personal-assistantflynntknapp@DELL-DESKTOP:~/Programming/personal-assistant$
```

**Explaining Django error**

The user is asking about a `RuntimeError` related to `populate()`. This error occurs because `django.setup()` is being called twice, which isn't allowed. Essentially, the Apps registry’s `populate()` method is designed to prevent recursion, meaning it can't run while already in progress. This issue often arises when something in `INSTALLED_APPS` triggers `django.setup()` again, like circular imports or improper calls in code like `settings.py`, `wsgi.py`, or `urls.py`. It’s likely an import issue causing this recursion.


Thought for 9 seconds


When you run:

```bash
python manage.py check --deploy
```

You’re invoking Django’s “system check” framework, specifically the suite of checks meant to flag missing or insecure production-deployment settings (HSTS, SSL redirects, secure cookies, etc.).

---

### Walking through the traceback

1. **`manage.py` → `main()`**
   This is just the standard Django bootstrap.

2. **`execute_from_command_line(sys.argv)`**
   Parses your command (`check --deploy`) and kicks off the management utility.

3. **`django.setup()`**
   Sets up Django’s internals: configures settings, logging, and—crucially—loads all your apps.

4. **`apps.populate(settings.INSTALLED_APPS)`**
   Builds the “app registry” by importing each app in your `INSTALLED_APPS`.

5. **RuntimeError: `populate() isn’t reentrant`**
   This error is raised when Django’s app‐registry `populate()` method is called *while it’s already running*. In other words, you’ve somehow triggered a second call to `populate()` before the first one finished. Django guards against this because re-initializing the registry mid-boot can leave things in a broken state.

---

### What “reentrant” means here

* **Non-reentrant** code: can’t safely be entered again before its first invocation completes.
* Django’s app registry is non-reentrant: you must only call `django.setup()`/`apps.populate()` once during startup.

---

### Common causes

1. **Manual `django.setup()` in your own code**
   If you’ve imported and invoked `django.setup()` (or indirectly triggered it) from inside an app’s module at import time, you’ll re-enter the setup process.

2. **Circular imports involving `django.setup()`**
   For example, if your `settings.py` or an `apps.py` file imports something that, in turn, calls `django.setup()`, you’ll get a nested call.

3. **Misplaced code in `__init__.py`**
   Anything you run at import time in your app packages should *not* invoke Django’s configuration routines.

---

### How to track it down

1. **Search for `django.setup()`** in your project—make sure the only call is the one in `manage.py`.
2. Grep for any file importing Django models or settings at top-level code that might implicitly trigger setup.
3. Temporarily add a print or breakpoint in your `manage.py` right before and after `django.setup()` to see if it ever fires twice.

---

### Quick fix checklist

* **Remove any extra `django.setup()`** calls outside of `manage.py`.
* **Avoid executing Django-dependent code at import time** in your apps (e.g. don’t query models or import management utilities in `apps.py.__init__` or module-level code).

Once you ensure that `django.setup()` only runs once, the “populate() isn’t reentrant” error will go away, and your `check --deploy` will complete normally.

## Location of `setup.py`
- This `setup.py` file is located in `config/celery.py` in the project directory.
![`setup.py` location](images/setup_py_location.png)